Workbook

Sheet 📊 Dashboard
B1: 📊 Dashboard | D1: 📅 Calendario | F1: 💰 Finanzas | H1: 🤝 CRM | J1: 🏢 Clientes | L1: 📈 Métricas
B2: PASCALL · Social Media Command Center | K2: Actualizado: March 2026
B7: 👥 CLIENTES ACTIVOS | F7: 💵 INGRESOS MES | J7: 📈 ROAS PROMEDIO | N7: 📣 PUBLICACIONES MES
B8: =COUNTA('🏢 Clientes'!B4:B53) -> 6 | F8: ='💰 Finanzas'!C6 -> 71000 | J8: ='💰 Finanzas'!C12 -> 3.40625 | N8: =COUNTA('📅 Calendario'!D4:D200) -> 8
B13: 💸 GASTOS MES | F13: 📊 MARGEN NETO | J13: 🎯 CPL PROMEDIO | N13: 🤝 COLABORACIONES
B14: ='💰 Finanzas'!C7 -> 21000 | F14: ='💰 Finanzas'!C8 -> 50000 | J14: ='💰 Finanzas'!C13 -> 91.428571 | N14: =COUNTA('🤝 CRM'!B4:B103) -> 10
B19: 🏢 ESTADO DE CLIENTES
B20: Cliente | C20: Plataformas | D20: Posts/Mes | E20: Inversión MXN | F20: ROAS | G20: Estado
B21: Clínica Derma Norte | C21: IG · FB · TT | D21: 20 | E21: 15000 | F21: 3.2 | G21: Activo
B22: Restaurante El Cobre | C22: IG · FB | D22: 15 | E22: 8000 | F22: 2.8 | G22: Activo
B23: Academia Fit MTY | C23: IG · TT · YT | D23: 30 | E23: 22000 | F23: 0 | G23: En pausa
B24: Boutique Cielito | C24: IG | D24: 12 | E24: 5000 | F24: 2.4 | G24: Activo
B25: Consultorio Dr. Pérez | C25: FB · Google | D25: 10 | E25: 12000 | F25: 4.1 | G25: Activo
B30: 🚦 SEMÁFORO DE METAS — ESTADO ACTUAL
B31: Métrica | C31: Valor Actual | D31: Meta Óptima | E31: Mínimo Aceptable | F31: Estado | G31: Acción Recomendada
B32: ROAS | C32: ='💰 Finanzas'!C12 -> 3.40625 | D32: 3 | E32: 1.5 | F32: =IF(C32>=3,"🟢 META SUPERADA",IF(C32>=1.5,"🟡 EN RANGO","🔴 BAJO META")) -> 🟢 META SUPERADA | G32: Mantén mix de contenido actual. Prueba nuevos segmentos.
B33: Margen % | C33: ='💰 Finanzas'!C9 -> 0.70422535 | D33: 0.5 | E33: 0.3 | F33: =IF(C33>=0.5,"🟢 META SUPERADA",IF(C33>=0.3,"🟡 EN RANGO","🔴 BAJO META")) -> 🟢 META SUPERADA | G33: Revisa estructura de costos. Considera paquetes premium.
B34: CPL MXN | C34: ='💰 Finanzas'!C13 -> 91.428571 | D34: 100 | E34: 200 | F34: =IF(C34<=100,"🟢 META SUPERADA",IF(C34<=200,"🟡 EN RANGO","🔴 ALTO")) -> 🟢 META SUPERADA | G34: Optimiza segmentación de anuncios y landing pages.
B35: Ingresos MXN | C35: ='💰 Finanzas'!C6 -> 71000 | D35: 120000 | E35: 80000 | F35: =IF(C35>=80000,"🟢 META SUPERADA",IF(C35>=50000,"🟡 EN RANGO","🔴 BAJO META")) -> 🟡 EN RANGO | G35: Activa prospección de 2 clientes nuevos este mes.
B39: 🔽 EMBUDO DE CONVERSIÓN — ESTE MES
B40: Etapa | E40: Volumen | H40: Tasa de Conversión | K40: Visual
B41: 👁️ Alcance Total | E41: =SUM('📈 Métricas'!F6:F12) -> 310000 | H41: 100% (base) | K41: IIIIIIIIIIIIIIIIIIIII
B42: 💬 Engagement | E42: =SUMPRODUCT(('📈 Métricas'!F6:F12)*('📈 Métricas'!H6:H12)) -> 19435 | H42: =IF(E41>0,E42/E41,0) -> 0.062693548 | K42: IIIIIIIIIIIII
B43: 🖱️ Clics al Perfil | E43: =SUM('📈 Métricas'!K6:K12) -> 6690 | H43: =IF(E41>0,E43/E41,0) -> 0.021580645 | K43: IIIIIII
B44: 🎯 Leads Generados | E44: =SUM('💰 Finanzas'!H35:H49) -> 350 | H44: =IF(E41>0,E44/E41,0) -> 0.0011290323 | K44: IIII
B45: 💰 Ventas / Cierres | E45: =ROUND(E44*0.3,0) -> 105 | H45: =IF(E44>0,E45/E44,0) -> 0.3 | K45: II

Sheet 📅 Calendario
B1: 📊 Dashboard | D1: 📅 Calendario | F1: 💰 Finanzas | H1: 🤝 CRM | J1: 🏢 Clientes | L1: 📈 Métricas
B2: 📅 PLANIFICADOR DE CONTENIDO — MULTI-CLIENTE
B3: Usa los filtros de Excel para ver por cliente, plataforma o estado →
B4: Cliente | C4: Fecha | D4: Contenido / Copy | E4: Plataforma | F4: Formato | G4: Estado | H4: Responsable | I4: Copy Aprobado | J4: Assets Listos | K4: Fecha Publicación | L4: Alcance Real | M4: Engagement % | N4: % Progreso | O4: Barra | P4: Eficiencia
B5: Clínica Derma Norte | C5: 46105 | D5: Tips de cuidado solar ☀️ | E5: Instagram | F5: Reels | G5: En producción | H5: Ben | I5: Sí | J5: Sí | K5: 46107 | L5: 8500 | M5: 4.2% | N5: =((IF(I5="Sí",1,0))+(IF(J5="Sí",1,0))+(IF(OR(G5="Aprobado",G5="Programado",G5="Publicado"),1,0)))/3 -> 0.66666667 | O5: =REPT("█",ROUND(N5*10,0))&REPT("░",10-ROUND(N5*10,0)) -> ███████░░░
B6: Clínica Derma Norte | C6: 46107 | D6: Antes y después tratamiento | E6: Facebook | F6: Carrusel | G6: Aprobado | H6: Ben | I6: Sí | J6: Sí | K6: 46108 | N6: =((IF(I6="Sí",1,0))+(IF(J6="Sí",1,0))+(IF(OR(G6="Aprobado",G6="Programado",G6="Publicado"),1,0)))/3 -> 1 | O6: =REPT("█",ROUND(N6*10,0))&REPT("░",10-ROUND(N6*10,0)) -> ██████████
B7: Restaurante El Cobre | C7: 46106 | D7: Especial fin de semana 🍽️ | E7: Instagram | F7: Post | G7: Idea | H7: Socio Marketing | I7: No | J7: No | N7: =((IF(I7="Sí",1,0))+(IF(J7="Sí",1,0))+(IF(OR(G7="Aprobado",G7="Programado",G7="Publicado"),1,0)))/3 -> 0 | O7: =REPT("█",ROUND(N7*10,0))&REPT("░",10-ROUND(N7*10,0)) -> ░░░░░░░░░░
B8: Academia Fit MTY | C8: 46109 | D8: Rutina de 7 minutos | E8: TikTok | F8: Reels | G8: En producción | H8: Ben | I8: Sí | J8: No | K8: 46111 | N8: =((IF(I8="Sí",1,0))+(IF(J8="Sí",1,0))+(IF(OR(G8="Aprobado",G8="Programado",G8="Publicado"),1,0)))/3 -> 0.33333333 | O8: =REPT("█",ROUND(N8*10,0))&REPT("░",10-ROUND(N8*10,0)) -> ███░░░░░░░
B9: Boutique Cielito | C9: 46110 | D9: Lookbook Primavera 🌸 | E9: Instagram | F9: Carrusel | G9: En revisión | H9: Ben | I9: No | J9: Sí | N9: =((IF(I9="Sí",1,0))+(IF(J9="Sí",1,0))+(IF(OR(G9="Aprobado",G9="Programado",G9="Publicado"),1,0)))/3 -> 0.33333333 | O9: =REPT("█",ROUND(N9*10,0))&REPT("░",10-ROUND(N9*10,0)) -> ███░░░░░░░
B10: Consultorio Dr. Pérez | C10: 46113 | D10: Importancia del check anual | E10: Facebook | F10: Post | G10: Programado | H10: Ben | I10: Sí | J10: Sí | K10: 46113 | N10: =((IF(I10="Sí",1,0))+(IF(J10="Sí",1,0))+(IF(OR(G10="Aprobado",G10="Programado",G10="Publicado"),1,0)))/3 -> 1 | O10: =REPT("█",ROUND(N10*10,0))&REPT("░",10-ROUND(N10*10,0)) -> ██████████
B11: Clínica Derma Norte | C11: 46115 | D11: Q&A en vivo con dermatólogo | E11: Instagram | F11: Live | G11: Idea | H11: Ben | I11: No | J11: No | N11: =((IF(I11="Sí",1,0))+(IF(J11="Sí",1,0))+(IF(OR(G11="Aprobado",G11="Programado",G11="Publicado"),1,0)))/3 -> 0 | O11: =REPT("█",ROUND(N11*10,0))&REPT("░",10-ROUND(N11*10,0)) -> ░░░░░░░░░░
N12: =((IF(I12="Sí",1,0))+(IF(J12="Sí",1,0))+(IF(OR(G12="Aprobado",G12="Programado",G12="Publicado"),1,0)))/3 -> 0 | O12: =REPT("█",ROUND(N12*10,0))&REPT("░",10-ROUND(N12*10,0)) -> ░░░░░░░░░░
N13: =((IF(I13="Sí",1,0))+(IF(J13="Sí",1,0))+(IF(OR(G13="Aprobado",G13="Programado",G13="Publicado"),1,0)))/3 -> 0 | O13: =REPT("█",ROUND(N13*10,0))&REPT("░",10-ROUND(N13*10,0)) -> ░░░░░░░░░░
N14: =((IF(I14="Sí",1,0))+(IF(J14="Sí",1,0))+(IF(OR(G14="Aprobado",G14="Programado",G14="Publicado"),1,0)))/3 -> 0 | O14: =REPT("█",ROUND(N14*10,0))&REPT("░",10-ROUND(N14*10,0)) -> ░░░░░░░░░░
N15: =((IF(I15="Sí",1,0))+(IF(J15="Sí",1,0))+(IF(OR(G15="Aprobado",G15="Programado",G15="Publicado"),1,0)))/3 -> 0 | O15: =REPT("█",ROUND(N15*10,0))&REPT("░",10-ROUND(N15*10,0)) -> ░░░░░░░░░░
N16: =((IF(I16="Sí",1,0))+(IF(J16="Sí",1,0))+(IF(OR(G16="Aprobado",G16="Programado",G16="Publicado"),1,0)))/3 -> 0 | O16: =REPT("█",ROUND(N16*10,0))&REPT("░",10-ROUND(N16*10,0)) -> ░░░░░░░░░░
N17: =((IF(I17="Sí",1,0))+(IF(J17="Sí",1,0))+(IF(OR(G17="Aprobado",G17="Programado",G17="Publicado"),1,0)))/3 -> 0 | O17: =REPT("█",ROUND(N17*10,0))&REPT("░",10-ROUND(N17*10,0)) -> ░░░░░░░░░░
N18: =((IF(I18="Sí",1,0))+(IF(J18="Sí",1,0))+(IF(OR(G18="Aprobado",G18="Programado",G18="Publicado"),1,0)))/3 -> 0 | O18: =REPT("█",ROUND(N18*10,0))&REPT("░",10-ROUND(N18*10,0)) -> ░░░░░░░░░░
N19: =((IF(I19="Sí",1,0))+(IF(J19="Sí",1,0))+(IF(OR(G19="Aprobado",G19="Programado",G19="Publicado"),1,0)))/3 -> 0 | O19: =REPT("█",ROUND(N19*10,0))&REPT("░",10-ROUND(N19*10,0)) -> ░░░░░░░░░░
N20: =((IF(I20="Sí",1,0))+(IF(J20="Sí",1,0))+(IF(OR(G20="Aprobado",G20="Programado",G20="Publicado"),1,0)))/3 -> 0 | O20: =REPT("█",ROUND(N20*10,0))&REPT("░",10-ROUND(N20*10,0)) -> ░░░░░░░░░░
N21: =((IF(I21="Sí",1,0))+(IF(J21="Sí",1,0))+(IF(OR(G21="Aprobado",G21="Programado",G21="Publicado"),1,0)))/3 -> 0 | O21: =REPT("█",ROUND(N21*10,0))&REPT("░",10-ROUND(N21*10,0)) -> ░░░░░░░░░░
N22: =((IF(I22="Sí",1,0))+(IF(J22="Sí",1,0))+(IF(OR(G22="Aprobado",G22="Programado",G22="Publicado"),1,0)))/3 -> 0 | O22: =REPT("█",ROUND(N22*10,0))&REPT("░",10-ROUND(N22*10,0)) -> ░░░░░░░░░░
N23: =((IF(I23="Sí",1,0))+(IF(J23="Sí",1,0))+(IF(OR(G23="Aprobado",G23="Programado",G23="Publicado"),1,0)))/3 -> 0 | O23: =REPT("█",ROUND(N23*10,0))&REPT("░",10-ROUND(N23*10,0)) -> ░░░░░░░░░░
... N204: =((IF(I204="Sí",1,0))+(IF(J204="Sí",1,0))+(IF(OR(G204="Aprobado",G204="Programado",G204="Publicado"),1,0)))/3 -> 0 | O204: =REPT("█",ROUND(N204*10,0))&REPT("░",10-ROUND(N204*10,0)) -> ░░░░░░░░░░

Sheet 💰 Finanzas
B1: 📊 Dashboard | D1: 📅 Calendario | F1: 💰 Finanzas | H1: 🤝 CRM | J1: 🏢 Clientes | L1: 📈 Métricas
B2: 💰 CENTRO FINANCIERO — SOCIAL MEDIA
B4: ⚡ KPIs CLAVE DEL MES
B5: Métrica | C5: Valor | D5: Meta | E5: Vs Meta
B6: Ingresos Totales MXN | C6: =SUM(D35:D39) -> 71000 | D6: 120000 | E6: =C6-D6 -> -49000
B7: Gastos Totales MXN | C7: =SUM(E35:E39) -> 21000 | D7: 60000 | E7: =C7-D7 -> -39000
B8: Margen Neto MXN | C8: =C6-C7 -> 50000 | D8: 60000 | E8: =C8-D8 -> -10000
B9: Margen % | C9: =IF(C6>0,(C6-C7)/C6,0) -> 0.70422535 | D9: 0.5 | E9: =C9-D9 -> 0.20422535
B10: Inversión Publicitaria MXN | C10: =SUM(F35:F39) -> 32000 | D10: 30000 | E10: =C10-D10 -> 2000
B11: Retorno Publicitario MXN | C11: =SUM(G35:G39) -> 109000 | D11: 90000 | E11: =C11-D11 -> 19000
B12: ROAS Promedio | C12: =IF(C10>0,C11/C10,0) -> 3.40625 | D12: 3 | E12: =C12-D12 -> 0.40625
B13: CPL Promedio MXN | C13: =IF(SUM(H35:H39)>0,C10/SUM(H35:H39),0) -> 91.428571 | D13: 80 | E13: =C13-D13 -> 11.428571
B14: ROI % | C14: =IF(C10>0,(C11-C10)/C10,0) -> 2.40625 | D14: 1 | E14: =C14-D14 -> 1.40625
B17: 📆 SEGUIMIENTO MENSUAL — 12 MESES
B18: Mes | C18: Clientes | D18: Ingresos MXN | E18: Gastos MXN | F18: Margen MXN | G18: Margen % | H18: Inv. Publi. | I18: Retorno | J18: ROAS | K18: CPL | L18: Leads | M18: ROI %
B19: Enero | C19: 8 | D19: 95000 | E19: 48000 | F19: =D19-E19 -> 47000 | G19: =IF(D19>0,(D19-E19)/D19,0) -> 0.49473684 | H19: 22000 | I19: 68000 | J19: =IF(H19>0,I19/H19,0) -> 3.0909091 | K19: =IF(J19>0,H19/J19,0) -> 7117.6471 | L19: 280 | M19: =IF(E19>0,(D19-E19)/E19,0) -> 0.97916667
B20: Febrero | C20: 8 | D20: 98000 | E20: 49000 | F20: =D20-E20 -> 49000 | G20: =IF(D20>0,(D20-E20)/D20,0) -> 0.5 | H20: 23000 | I20: 72000 | J20: =IF(H20>0,I20/H20,0) -> 3.1304348 | K20: =IF(J20>0,H20/J20,0) -> 7347.2222 | L20: 295 | M20: =IF(E20>0,(D20-E20)/E20,0) -> 1
B21: Marzo | C21: 9 | D21: 110000 | E21: 52000 | F21: =D21-E21 -> 58000 | G21: =IF(D21>0,(D21-E21)/D21,0) -> 0.52727273 | H21: 28000 | I21: 85000 | J21: =IF(H21>0,I21/H21,0) -> 3.0357143 | K21: =IF(J21>0,H21/J21,0) -> 9223.5294 | L21: 320 | M21: =IF(E21>0,(D21-E21)/E21,0) -> 1.1153846
B22: Abril | F22: =D22-E22 -> 0 | G22: =IF(D22>0,(D22-E22)/D22,0) -> 0 | J22: =IF(H22>0,I22/H22,0) -> 0 | K22: =IF(J22>0,H22/J22,0) -> 0 | M22: =IF(E22>0,(D22-E22)/E22,0) -> 0
B23: Mayo | F23: =D23-E23 -> 0 | G23: =IF(D23>0,(D23-E23)/D23,0) -> 0 | J23: =IF(H23>0,I23/H23,0) -> 0 | K23: =IF(J23>0,H23/J23,0) -> 0 | M23: =IF(E23>0,(D23-E23)/E23,0) -> 0
B24: Junio | F24: =D24-E24 -> 0 | G24: =IF(D24>0,(D24-E24)/D24,0) -> 0 | J24: =IF(H24>0,I24/H24,0) -> 0 | K24: =IF(J24>0,H24/J24,0) -> 0 | M24: =IF(E24>0,(D24-E24)/E24,0) -> 0
B25: Julio | F25: =D25-E25 -> 0 | G25: =IF(D25>0,(D25-E25)/D25,0) -> 0 | J25: =IF(H25>0,I25/H25,0) -> 0 | K25: =IF(J25>0,H25/J25,0) -> 0 | M25: =IF(E25>0,(D25-E25)/E25,0) -> 0
B26: Agosto | F26: =D26-E26 -> 0 | G26: =IF(D26>0,(D26-E26)/D26,0) -> 0 | J26: =IF(H26>0,I26/H26,0) -> 0 | K26: =IF(J26>0,H26/J26,0) -> 0 | M26: =IF(E26>0,(D26-E26)/E26,0) -> 0
B27: Septiembre | F27: =D27-E27 -> 0 | G27: =IF(D27>0,(D27-E27)/D27,0) -> 0 | J27: =IF(H27>0,I27/H27,0) -> 0 | K27: =IF(J27>0,H27/J27,0) -> 0 | M27: =IF(E27>0,(D27-E27)/E27,0) -> 0
B28: Octubre | F28: =D28-E28 -> 0 | G28: =IF(D28>0,(D28-E28)/D28,0) -> 0 | J28: =IF(H28>0,I28/H28,0) -> 0 | K28: =IF(J28>0,H28/J28,0) -> 0 | M28: =IF(E28>0,(D28-E28)/E28,0) -> 0
B29: Noviembre | F29: =D29-E29 -> 0 | G29: =IF(D29>0,(D29-E29)/D29,0) -> 0 | J29: =IF(H29>0,I29/H29,0) -> 0 | K29: =IF(J29>0,H29/J29,0) -> 0 | M29: =IF(E29>0,(D29-E29)/E29,0) -> 0
B30: Diciembre | F30: =D30-E30 -> 0 | G30: =IF(D30>0,(D30-E30)/D30,0) -> 0 | J30: =IF(H30>0,I30/H30,0) -> 0 | K30: =IF(J30>0,H30/J30,0) -> 0 | M30: =IF(E30>0,(D30-E30)/E30,0) -> 0
B31: TOTAL ANUAL | C31: =COUNTA(C19:C30) -> 3 | D31: =SUM(D19:D30) -> 303000 | E31: =SUM(E19:E30) -> 149000 | F31: =SUM(F19:F30) -> 154000 | G31: =IF(D31>0,(D31-E31)/D31,0) -> 0.50825083 | H31: =SUM(H19:H30) -> 73000 | I31: =SUM(I19:I30) -> 225000 | J31: =IF(H31>0,I31/H31,0) -> 3.0821918 | K31: =IF(SUM(L19:L30)>0,H31/SUM(L19:L30),0) -> 81.564246 | L31: =SUM(L19:L30) -> 895 | M31: =IF(H31>0,(I31-H31)/H31,0) -> 2.0821918
B33: 🏢 DETALLE INGRESOS & GASTOS POR CLIENTE
B34: Cliente | C34: Servicio | D34: Honorarios MXN | E34: Gastos MXN | F34: Inv. Publi. | G34: Retorno | H34: Leads | I34: ROAS | J34: Margen %
B35: Clínica Derma Norte | C35: Community + Ads | D35: 18000 | E35: 5000 | F35: 12000 | G35: 38000 | H35: 120 | I35: =IF(F35>0,G35/F35,0) -> 3.1666667 | J35: =IF(D35>0,(D35-E35)/D35,0) -> 0.72222222
B36: Restaurante El Cobre | C36: Community | D36: 8000 | E36: 2000 | F36: 4000 | G36: 14000 | H36: 45 | I36: =IF(F36>0,G36/F36,0) -> 3.5 | J36: =IF(D36>0,(D36-E36)/D36,0) -> 0.75
B37: Academia Fit MTY | C37: Full Package | D37: 25000 | E37: 8000 | F37: 8000 | G37: 28000 | H37: 95 | I37: =IF(F37>0,G37/F37,0) -> 3.5 | J37: =IF(D37>0,(D37-E37)/D37,0) -> 0.68
B38: Boutique Cielito | C38: Community | D38: 6000 | E38: 1500 | F38: 2000 | G38: 7000 | H38: 30 | I38: =IF(F38>0,G38/F38,0) -> 3.5 | J38: =IF(D38>0,(D38-E38)/D38,0) -> 0.75
B39: Consultorio Dr. Pérez | C39: Community + Ads | D39: 14000 | E39: 4500 | F39: 6000 | G39: 22000 | H39: 60 | I39: =IF(F39>0,G39/F39,0) -> 3.6666667 | J39: =IF(D39>0,(D39-E39)/D39,0) -> 0.67857143
B42: ⏱️ RENTABILIDAD POR HORA — ANÁLISIS DE EFICIENCIA
B43: Cliente | C43: Honorarios | D43: Horas/Mes | E43: Tarifa Real $/h | F43: Margen/h | G43: Eficiencia | H43: Semáforo
B44: Clínica Derma Norte | C44: 18000 | D44: 65 | E44: =C44/D44 -> 276.92308 | F44: 5000 | G44: =(C44-F44)/D44 -> 200 | H44: =IF(E44>=300,"🟢 Premium",IF(E44>=200,"🟡 Estándar","🔴 Revisar precio")) -> 🟡 Estándar
B45: Restaurante El Cobre | C45: 8000 | D45: 30 | E45: =C45/D45 -> 266.66667 | F45: 2000 | G45: =(C45-F45)/D45 -> 200 | H45: =IF(E45>=300,"🟢 Premium",IF(E45>=200,"🟡 Estándar","🔴 Revisar precio")) -> 🟡 Estándar
B46: Academia Fit MTY | C46: 25000 | D46: 90 | E46: =C46/D46 -> 277.77778 | F46: 8000 | G46: =(C46-F46)/D46 -> 188.88889 | H46: =IF(E46>=300,"🟢 Premium",IF(E46>=200,"🟡 Estándar","🔴 Revisar precio")) -> 🟡 Estándar
...

Sheet 🤝 CRM
B1: 📊 Dashboard | D1: 📅 Calendario | F1: 💰 Finanzas | H1: 🤝 CRM | J1: 🏢 Clientes | L1: 📈 Métricas
B2: 🤝 CRM — COLABORACIONES Y CONTACTOS CLAVE
B4: ⚡ RESUMEN RÁPIDO
B5: Total Contactos | D5: Activos | F5: En negociación | H5: Cerrados
B6: =COUNTA(B9:B108) -> 6 | D6: =COUNTIF(G9:G108,"Activo") -> 4 | F6: =COUNTIF(G9:G108,"En negociación") -> 1 | H6: =COUNTIF(G9:G108,"Cerrado")+COUNTIF(G9:G108,"Completado") -> 0
B8: Nombre / Marca | C8: Tipo | D8: Plataforma | E8: Handle / Contacto | F8: Seguidores | G8: Estado | H8: Prioridad | I8: Tipo Collab | J8: Presupuesto MXN | K8: Fecha Contacto | L8: Próximo Paso | M8: Notas
B9: @dermbeauty.mty | C9: Influencer | D9: Instagram | E9: @dermbeauty.mty | F9: 85000 | G9: Activo | H9: Alta | I9: Pago | J9: 8000 | K9: 46068 | L9: Renovar contrato abril | M9: Tasa de eng. 4.8%
B10: Revista Estilo MTY | C10: Media | D10: Instagram · Impreso | E10: contacto@estiломty.mx | F10: 120000 | G10: En negociación | H10: Alta | I10: Canje | J10: 0 | K10: 46082 | L10: Enviar propuesta | M10: Interés en 2 clientes
B11: FitCoach Ramírez | C11: Creador de contenido | D11: TikTok | E11: @fitramirezmty | F11: 45000 | G11: Activo | H11: Media | I11: Barter | J11: 0 | K11: 46042 | L11: Medir resultados | M11: Collab con Academia Fit
B12: Agencia Pixel | C12: Aliado estratégico | D12: LinkedIn | E12: hola@pixelagency.mx | F12: 0 | G12: Activo | H12: Alta | I12: Co-producción | J12: 0 | K12: 46091 | L12: Reunión semanal | M12: Referidos mutuos
B13: @foodiesmty | C13: Influencer | D13: Instagram · TikTok | E13: @foodiesmty | F13: 210000 | G13: Prospecto | H13: Alta | I13: Por definir | J13: 0 | K13: 46099 | L13: Enviar DM | M13: Perfecto para El Cobre
B14: Studio Luz Visual | C14: Proveedor | D14: — | E14: studio@luzvisual.mx | F14: 0 | G14: Activo | H14: Media | I14: Por definir | J14: 0 | K14: 46058 | L14: — | M14: Fotógrafos freelance
B120: 💎 CALCULADORA DE VALOR DE INFLUENCER
B121: Cruza seguidores con engagement real para calcular el fee justo y evitar pagar de más.
B122: Creador | C122: Plataforma | D122: Seguidores | E122: Eng% | F122: Eng Real | G122: CPM Ref. MXN | H122: Fee Justo/Post | I122: Fee Máximo | J122: Categoría | K122: Recomendación
B123: @dermbeauty.mty | C123: Instagram | D123: 85000 | E123: 0.048 | F123: =IF(D123*E123>0,D123*E123,"") -> 4080 | G123: =IF(C123="Instagram",120,IF(C123="TikTok",80,IF(C123="YouTube",200,IF(C123="Facebook",60,100)))) -> 120 | H123: =IF(D123>0,ROUND((D123/1000)*G123*(1+E123*5),0),"") -> 12648 | I123: =IF(H123>0,ROUND(H123*1.2,0),"") -> 15178 | J123: =IF(D123="","",IF(D123>=1000000,"🌟 Macro",IF(D123>=100000,"⭐ Mid-tier",IF(D123>=10000,"✨ Micro","🔸 Nano")))) -> ✨ Micro | K123: =IF(D123="","",IF(E123>=0.06,"💚 Alto engagement - Priorizar",IF(E123>=0.03,"💛 Engagement promedio",IF(D123>=0,"🔴 Bajo engagement - Negociar precio","")))) -> 💛 Engagement promedio
B124: FitCoach Ramírez | C124: TikTok | D124: 45000 | E124: 0.084 | F124: =IF(D124*E124>0,D124*E124,"") -> 3780 | G124: =IF(C124="Instagram",120,IF(C124="TikTok",80,IF(C124="YouTube",200,IF(C124="Facebook",60,100)))) -> 80 | H124: =IF(D124>0,ROUND((D124/1000)*G124*(1+E124*5),0),"") -> 5112 | I124: =IF(H124>0,ROUND(H124*1.2,0),"") -> 6134 | J124: =IF(D124="","",IF(D124>=1000000,"🌟 Macro",IF(D124>=100000,"⭐ Mid-tier",IF(D124>=10000,"✨ Micro","🔸 Nano")))) -> ✨ Micro | K124: =IF(D124="","",IF(E124>=0.06,"💚 Alto engagement - Priorizar",IF(E124>=0.03,"💛 Engagement promedio",IF(D124>=0,"🔴 Bajo engagement - Negociar precio","")))) -> 💚 Alto engagement - Priorizar
B125: @foodiesmty | C125: Instagram | D125: 210000 | E125: 0.032 | F125: =IF(D125*E125>0,D125*E125,"") -> 6720 | G125: =IF(C125="Instagram",120,IF(C125="TikTok",80,IF(C125="YouTube",200,IF(C125="Facebook",60,100)))) -> 120 | H125: =IF(D125>0,ROUND((D125/1000)*G125*(1+E125*5),0),"") -> 29232 | I125: =IF(H125>0,ROUND(H125*1.2,0),"") -> 35078 | J125: =IF(D125="","",IF(D125>=1000000,"🌟 Macro",IF(D125>=100000,"⭐ Mid-tier",IF(D125>=10000,"✨ Micro","🔸 Nano")))) -> ⭐ Mid-tier | K125: =IF(D125="","",IF(E125>=0.06,"💚 Alto engagement - Priorizar",IF(E125>=0.03,"💛 Engagement promedio",IF(D125>=0,"🔴 Bajo engagement - Negociar precio","")))) -> 💛 Engagement promedio
B126: Canal Salud MTY | C126: YouTube | D126: 28000 | E126: 0.065 | F126: =IF(D126*E126>0,D126*E126,"") -> 1820 | G126: =IF(C126="Instagram",120,IF(C126="TikTok",80,IF(C126="YouTube",200,IF(C126="Facebook",60,100)))) -> 200 | H126: =IF(D126>0,ROUND((D126/1000)*G126*(1+E126*5),0),"") -> 7420 | I126: =IF(H126>0,ROUND(H126*1.2,0),"") -> 8904 | J126: =IF(D126="","",IF(D126>=1000000,"🌟 Macro",IF(D126>=100000,"⭐ Mid-tier",IF(D126>=10000,"✨ Micro","🔸 Nano")))) -> ✨ Micro | K126: =IF(D126="","",IF(E126>=0.06,"💚 Alto engagement - Priorizar",IF(E126>=0.03,"💛 Engagement promedio",IF(D126>=0,"🔴 Bajo engagement - Negociar precio","")))) -> 💚 Alto engagement - Priorizar
C127: Instagram | F127: =IF(D127*E127>0,D127*E127,"") | G127: =IF(C127="Instagram",120,IF(C127="TikTok",80,IF(C127="YouTube",200,IF(C127="Facebook",60,100)))) -> 120 | H127: =IF(ISNUMBER(D127),ROUND((D127/1000)*G127*(1+IF(ISNUMBER(E127),E127,0)*5),0),"") | I127: =IF(ISNUMBER(H127),ROUND(H127*1.2,0),"") | J127: =IF(D127="","",IF(D127>=1000000,"🌟 Macro",IF(D127>=100000,"⭐ Mid-tier",IF(D127>=10000,"✨ Micro","🔸 Nano")))) | K127: =IF(OR(D127="",D127=0),"",IF(E127>=0.06,"💚 Alto eng. - Priorizar",IF(E127>=0.03,"💛 Promedio - OK","🔴 Bajo eng.")))
C128: TikTok | F128: =IF(D128*E128>0,D128*E128,"") | G128: =IF(C128="Instagram",120,IF(C128="TikTok",80,IF(C128="YouTube",200,IF(C128="Facebook",60,100)))) -> 80 | H128: =IF(ISNUMBER(D128),ROUND((D128/1000)*G128*(1+IF(ISNUMBER(E128),E128,0)*5),0),"") | I128: =IF(ISNUMBER(H128),ROUND(H128*1.2,0),"") | J128: =IF(D128="","",IF(D128>=1000000,"🌟 Macro",IF(D128>=100000,"⭐ Mid-tier",IF(D128>=10000,"✨ Micro","🔸 Nano")))) | K128: =IF(OR(D128="",D128=0),"",IF(E128>=0.06,"💚 Alto eng. - Priorizar",IF(E128>=0.03,"💛 Promedio - OK","🔴 Bajo eng.")))

Sheet 🏢 Clientes
B1: 📊 Dashboard | D1: 📅 Calendario | F1: 💰 Finanzas | H1: 🤝 CRM | J1: 🏢 Clientes | L1: 📈 Métricas
B2: 🏢 DIRECTORIO DE CLIENTES — PASCALL GROUP
B3: 📋 CLIENTES ACTIVOS Y CARTERA
B4: Empresa / Marca | C4: Industria | D4: Contacto Principal | E4: Tel / WhatsApp | F4: Email | G4: Plataformas | H4: Paquete MXN/mes | I4: Fecha Inicio | J4: Renovación | K4: Estado | L4: Score
B5: Clínica Derma Norte | C5: Salud & Belleza | D5: Dra. Laura Vega | E5: 81 1234 5678 | F5: lvega@dermante.mx | G5: IG·FB·TT | H5: 15000 | I5: 45901 | J5: 46266 | K5: Activo | L5: =REPT("★",5) -> ★★★★★
B6: Restaurante El Cobre | C6: Gastronomía | D6: Carlos Mendoza | E6: 81 9876 5432 | F6: carlos@elcobre.mx | G6: IG·FB | H6: 8000 | I6: 45962 | J6: 46327 | K6: Activo | L6: =REPT("★",5) -> ★★★★★
B7: Academia Fit MTY | C7: Fitness & Salud | D7: Sofía Reyes | E7: 81 5555 1212 | F7: sofia@academiafit.mx | G7: IG·TT·YT | H7: 22000 | I7: 45931 | J7: 46296 | K7: En pausa | L7: =REPT("★",5) -> ★★★★★
B8: Boutique Cielito | C8: Moda & Retail | D8: Ana Torres | E8: 81 3344 5566 | F8: ana@cielito.mx | G8: IG | H8: 5000 | I8: 46023 | J8: 46388 | K8: Activo | L8: =REPT("★",5) -> ★★★★★
B9: Consultorio Dr. Pérez | C9: Salud | D9: Dr. Mario Pérez | E9: 81 7788 9900 | F9: mario@drperez.mx | G9: FB·Google | H9: 12000 | I9: 46054 | J9: 46419 | K9: Activo | L9: =REPT("★",5) -> ★★★★★

Sheet 📈 Métricas
B1: 📊 Dashboard | D1: 📅 Calendario | F1: 💰 Finanzas | H1: 🤝 CRM | J1: 🏢 Clientes | L1: 📈 Métricas
B2: 📈 MÉTRICAS DE RENDIMIENTO POR CLIENTE
B4: 🎯 KPIs POR RED SOCIAL — MES ACTUAL
B5: Cliente / Cuenta | C5: Plataforma | D5: Seguidores | E5: Nuevos Segs | F5: Alcance | G5: Impresiones | H5: Engagement % | I5: Publicaciones | J5: Guardados | K5: Clics al Perfil | L5: Score Eficiencia | M5: Vs Promedio | N5: Eng% Ant. | O5: △ Eng%
B6: Clínica Derma Norte | C6: Instagram | D6: 12400 | E6: 320 | F6: 45000 | G6: 98000 | H6: 0.048 | I6: 20 | J6: 890 | K6: 1240 | L6: =F6*H6*I6 -> 43200 | M6: =IF(L6>AVERAGE($L$6:$L$12),"⬆️ Sobre prom.","⬇️ Bajo prom.") -> ⬇️ Bajo prom. | O6: =IF(N6="","—",IF(H6>N6,"⬆️ "&TEXT(H6-N6,"0.0%"),"⬇️ "&TEXT(H6-N6,"0.0%"))) -> —
B7: Clínica Derma Norte | C7: Facebook | D7: 8200 | E7: 85 | F7: 22000 | G7: 41000 | H7: 0.021 | I7: 12 | J7: 220 | K7: 380 | L7: =F7*H7*I7 -> 5544 | M7: =IF(L7>AVERAGE($L$6:$L$12),"⬆️ Sobre prom.","⬇️ Bajo prom.") -> ⬇️ Bajo prom. | O7: =IF(N7="","—",IF(H7>N7,"⬆️ "&TEXT(H7-N7,"0.0%"),"⬇️ "&TEXT(H7-N7,"0.0%"))) -> —
B8: Restaurante El Cobre | C8: Instagram | D8: 6800 | E8: 140 | F8: 18000 | G8: 35000 | H8: 0.052 | I8: 15 | J8: 410 | K8: 620 | L8: =F8*H8*I8 -> 14040 | M8: =IF(L8>AVERAGE($L$6:$L$12),"⬆️ Sobre prom.","⬇️ Bajo prom.") -> ⬇️ Bajo prom. | O8: =IF(N8="","—",IF(H8>N8,"⬆️ "&TEXT(H8-N8,"0.0%"),"⬇️ "&TEXT(H8-N8,"0.0%"))) -> —
B9: Academia Fit MTY | C9: Instagram | D9: 22000 | E9: 580 | F9: 85000 | G9: 160000 | H9: 0.061 | I9: 30 | J9: 2100 | K9: 3400 | L9: =F9*H9*I9 -> 155550 | M9: =IF(L9>AVERAGE($L$6:$L$12),"⬆️ Sobre prom.","⬇️ Bajo prom.") -> ⬆️ Sobre prom. | O9: =IF(N9="","—",IF(H9>N9,"⬆️ "&TEXT(H9-N9,"0.0%"),"⬇️ "&TEXT(H9-N9,"0.0%"))) -> —
B10: Academia Fit MTY | C10: TikTok | D10: 15500 | E10: 1200 | F10: 120000 | G10: 280000 | H10: 0.084 | I10: 20 | J10: 0 | K10: 0 | L10: =F10*H10*I10 -> 201600 | M10: =IF(L10>AVERAGE($L$6:$L$12),"⬆️ Sobre prom.","⬇️ Bajo prom.") -> ⬆️ Sobre prom. | O10: =IF(N10="","—",IF(H10>N10,"⬆️ "&TEXT(H10-N10,"0.0%"),"⬇️ "&TEXT(H10-N10,"0.0%"))) -> —
B11: Boutique Cielito | C11: Instagram | D11: 4200 | E11: 95 | F11: 12000 | G11: 22000 | H11: 0.039 | I11: 12 | J11: 560 | K11: 840 | L11: =F11*H11*I11 -> 5616 | M11: =IF(L11>AVERAGE($L$6:$L$12),"⬆️ Sobre prom.","⬇️ Bajo prom.") -> ⬇️ Bajo prom. | O11: =IF(N11="","—",IF(H11>N11,"⬆️ "&TEXT(H11-N11,"0.0%"),"⬇️ "&TEXT(H11-N11,"0.0%"))) -> —
B12: Consultorio Dr. Pérez | C12: Facebook | D12: 3100 | E12: 45 | F12: 8000 | G12: 15000 | H12: 0.018 | I12: 10 | J12: 120 | K12: 210 | L12: =F12*H12*I12 -> 1440 | M12: =IF(L12>AVERAGE($L$6:$L$12),"⬆️ Sobre prom.","⬇️ Bajo prom.") -> ⬇️ Bajo prom. | O12: =IF(N12="","—",IF(H12>N12,"⬆️ "&TEXT(H12-N12,"0.0%"),"⬇️ "&TEXT(H12-N12,"0.0%"))) -> —
L13: =IF(AND(E13>0,G13>0),ROUND(E13*G13/1000,1),"") | M13: =IF(L13="","",IF(L13>AVERAGE(L6:L55),"⬆️ Sobre prom.","⬇️ Bajo prom."))
L14: =IF(AND(E14>0,G14>0),ROUND(E14*G14/1000,1),"") | M14: =IF(L14="","",IF(L14>AVERAGE(L6:L55),"⬆️ Sobre prom.","⬇️ Bajo prom."))
L15: =IF(AND(E15>0,G15>0),ROUND(E15*G15/1000,1),"") | M15: =IF(L15="","",IF(L15>AVERAGE(L6:L55),"⬆️ Sobre prom.","⬇️ Bajo prom."))
L16: =IF(AND(E16>0,G16>0),ROUND(E16*G16/1000,1),"") | M16: =IF(L16="","",IF(L16>AVERAGE(L6:L55),"⬆️ Sobre prom.","⬇️ Bajo prom."))
L17: =IF(AND(E17>0,G17>0),ROUND(E17*G17/1000,1),"") | M17: =IF(L17="","",IF(L17>AVERAGE(L6:L55),"⬆️ Sobre prom.","⬇️ Bajo prom."))
L18: =IF(AND(E18>0,G18>0),ROUND(E18*G18/1000,1),"") | M18: =IF(L18="","",IF(L18>AVERAGE(L6:L55),"⬆️ Sobre prom.","⬇️ Bajo prom."))
L19: =IF(AND(E19>0,G19>0),ROUND(E19*G19/1000,1),"") | M19: =IF(L19="","",IF(L19>AVERAGE(L6:L55),"⬆️ Sobre prom.","⬇️ Bajo prom."))
L20: =IF(AND(E20>0,G20>0),ROUND(E20*G20/1000,1),"") | M20: =IF(L20="","",IF(L20>AVERAGE(L6:L55),"⬆️ Sobre prom.","⬇️ Bajo prom."))
L21: =IF(AND(E21>0,G21>0),ROUND(E21*G21/1000,1),"") | M21: =IF(L21="","",IF(L21>AVERAGE(L6:L55),"⬆️ Sobre prom.","⬇️ Bajo prom."))
L22: =IF(AND(E22>0,G22>0),ROUND(E22*G22/1000,1),"") | M22: =IF(L22="","",IF(L22>AVERAGE(L6:L55),"⬆️ Sobre prom.","⬇️ Bajo prom."))
L23: =IF(AND(E23>0,G23>0),ROUND(E23*G23/1000,1),"") | M23: =IF(L23="","",IF(L23>AVERAGE(L6:L55),"⬆️ Sobre prom.","⬇️ Bajo prom."))
L24: =IF(AND(E24>0,G24>0),ROUND(E24*G24/1000,1),"") | M24: =IF(L24="","",IF(L24>AVERAGE(L6:L55),"⬆️ Sobre prom.","⬇️ Bajo prom."))
L25: =IF(AND(E25>0,G25>0),ROUND(E25*G25/1000,1),"") | M25: =IF(L25="","",IF(L25>AVERAGE(L6:L55),"⬆️ Sobre prom.","⬇️ Bajo prom."))
L26: =IF(AND(E26>0,G26>0),ROUND(E26*G26/1000,1),"") | M26: =IF(L26="","",IF(L26>AVERAGE(L6:L55),"⬆️ Sobre prom.","⬇️ Bajo prom."))
L27: =IF(AND(E27>0,G27>0),ROUND(E27*G27/1000,1),"") | M27: =IF(L27="","",IF(L27>AVERAGE(L6:L55),"⬆️ Sobre prom.","⬇️ Bajo prom."))
L28: =IF(AND(E28>0,G28>0),ROUND(E28*G28/1000,1),"") | M28: =IF(L28="","",IF(L28>AVERAGE(L6:L55),"⬆️ Sobre prom.","⬇️ Bajo prom."))
L29: =IF(AND(E29>0,G29>0),ROUND(E29*G29/1000,1),"") | M29: =IF(L29="","",IF(L29>AVERAGE(L6:L55),"⬆️ Sobre prom.","⬇️ Bajo prom."))
L30: =IF(AND(E30>0,G30>0),ROUND(E30*G30/1000,1),"") | M30: =IF(L30="","",IF(L30>AVERAGE(L6:L55),"⬆️ Sobre prom.","⬇️ Bajo prom."))
L31: =IF(AND(E31>0,G31>0),ROUND(E31*G31/1000,1),"") | M31: =IF(L31="","",IF(L31>AVERAGE(L6:L55),"⬆️ Sobre prom.","⬇️ Bajo prom."))
L32: =IF(AND(E32>0,G32>0),ROUND(E32*G32/1000,1),"") | M32: =IF(L32="","",IF(L32>AVERAGE(L6:L55),"⬆️ Sobre prom.","⬇️ Bajo prom."))
L33: =IF(AND(E33>0,G33>0),ROUND(E33*G33/1000,1),"") | M33: =IF(L33="","",IF(L33>AVERAGE(L6:L55),"⬆️ Sobre prom.","⬇️ Bajo prom."))
L34: =IF(AND(E34>0,G34>0),ROUND(E34*G34/1000,1),"") | M34: =IF(L34="","",IF(L34>AVERAGE(L6:L55),"⬆️ Sobre prom.","⬇️ Bajo prom."))
L35: =IF(AND(E35>0,G35>0),ROUND(E35*G35/1000,1),"") | M35: =IF(L35="","",IF(L35>AVERAGE(L6:L55),"⬆️ Sobre prom.","⬇️ Bajo prom."))
L36: =IF(AND(E36>0,G36>0),ROUND(E36*G36/1000,1),"") | M36: =IF(L36="","",IF(L36>AVERAGE(L6:L55),"⬆️ Sobre prom.","⬇️ Bajo prom."))
L37: =IF(AND(E37>0,G37>0),ROUND(E37*G37/1000,1),"") | M37: =IF(L37="","",IF(L37>AVERAGE(L6:L55),"⬆️ Sobre prom.","⬇️ Bajo prom."))
L38: =IF(AND(E38>0,G38>0),ROUND(E38*G38/1000,1),"") | M38: =IF(L38="","",IF(L38>AVERAGE(L6:L55),"⬆️ Sobre prom.","⬇️ Bajo prom."))
L39: =IF(AND(E39>0,G39>0),ROUND(E39*G39/1000,1),"") | M39: =IF(L39="","",IF(L39>AVERAGE(L6:L55),"⬆️ Sobre prom.","⬇️ Bajo prom."))
L40: =IF(AND(E40>0,G40>0),ROUND(E40*G40/1000,1),"") | M40: =IF(L40="","",IF(L40>AVERAGE(L6:L55),"⬆️ Sobre prom.","⬇️ Bajo prom."))
L41: =IF(AND(E41>0,G41>0),ROUND(E41*G41/1000,1),"") | M41: =IF(L41="","",IF(L41>AVERAGE(L6:L55),"⬆️ Sobre prom.","⬇️ Bajo prom."))
...

Sheet ✍️ Copy & Hooks
B1: 📊 Dashboard | D1: 📅 Calendario | F1: 💰 Finanzas | H1: 🤝 CRM | J1: 🏢 Clientes | L1: 📈 Métricas | N1: ✍️ Copy & Hooks
B3: ✍️ BANCO DE HOOKS & ESTRUCTURAS DE COPY — Psicología de Ventas
B5: 🎣 HOOKS DE APERTURA (LOS PRIMEROS 3 SEGUNDOS SON TODO)
B6: Tipo de Hook | C6: Industria | D6: Estructura / Template | E6: Ejemplo Real
B7: Pregunta Provocadora | C7: Universal | D7: ÿ¿[Dolor del cliente]? Esto es lo que nadie te dice sobre [tema]. | E7: ¿Tu piel nunca mejora aunque gastes en cremas? Esto es lo que las marcas no quieren que sepas.
B8: Cifra Impactante | C8: Salud / Finanzas | D8: "[X]% de [audiencia] no sabe que [dato sorprendente]." | E8: "El 78% de las personas en Monterrey pierde más de $3,000 pesos al año en skincare ineficiente."
B9: Antes / Después | C9: Belleza / Fitness | D9: "De [estado negativo] a [resultado deseado] en [tiempo]." | E9: "De piel apagada a luminosa en 21 días. Esto fue lo único que cambié."
B10: El Secreto | C10: Cualquier nicho | D10: "Lo que los [expertos/marcas] no quieren que sepas sobre [tema]." | E10: "Lo que los restaurantes de lujo no quieren que sepas sobre sus platillos del día."
B11: Identificación directa | C11: Ecommerce / Servicios | D11: "Si eres [descripción específica], este post es para ti." | E11: "Si eres mamá en Monterrey y cuidas tu piel, este post es para ti."
B12: El Error Común | C12: Educativo | D12: "El error #1 que comete [audiencia] cuando [acción]." | E12: "El error #1 que cometen los emprendedores cuando contratan a un community manager."
B13: Promesa de Resultado | C13: Fitness / Negocios | D13: "[Resultado específico] sin [objeción principal]. Así es cómo." | E13: "Más clientes para tu clínica sin gastar en publicidad costosa. Así es cómo."
B14: Storytelling de Empatía | C14: Salud / Lifestyle | D14: "Hace [tiempo], yo también [problema]. Hoy [transformación]." | E14: "Hace 6 meses yo también pensaba que los Reels eran una pérdida de tiempo. Hoy generan el 60% de mis clientes."
B15: FOMO (Urgencia) | C15: Ecommerce / Eventos | D15: "Solo [X] lugares/piezas/días. [Beneficio] que no puedes dejar pasar." | E15: "Solo 5 lugares para nuestra consulta gratuita de esta semana. Tu piel no puede esperar."
B16: Social Proof | C16: Universal | D16: "[X] personas en [lugar] ya [resultado]. ¿Tú cuándo?." | E16: "847 pacientes en Monterrey ya recuperaron la confianza en su piel. ¿Tú cuándo?"
B19: 🏗️ ESTRUCTURAS DE COPY PROBADAS — FRAMEWORKS
B20: Framework | C20: Cuándo usarlo | D20: Estructura paso a paso | E20: Checklist
B21: AIDA | C21: Posts de venta directa, Ads | D21: A - ATENCIÓN: Hook impactante en línea 1 I - INTERÉS: Dato/historia que conecta D - DESEO: Beneficio específico + prueba social A - ACCIÓN: CTA claro y urgente | E21: ✅ Hook en <3 seg ✅ Beneficio antes de característica ✅ Un solo CTA ✅ Emojis estratégicos
B22: PAS | C22: Contenido educativo, problemas de audiencia | D22: P - PROBLEMA: Nombra el dolor exacto A - AGITACIÓN: Amplifica las consecuencias S - SOLUCIÓN: Presenta tu oferta como el alivio | E22: ✅ El problema debe doler ✅ No resolverlo demasiado rápido ✅ Solución específica, no genérica
B23: PASTOR | C23: Copy largo, emails, Reels de >60 seg | D23: P - Persona/Problema: ¿A quién hablas? A - Amplify: ¿Qué pasa si no lo resuelve? S - Story: Tu caso o el de un cliente T - Transformation: El después O - Offer: La propuesta R - Response: El CTA | E23: ✅ Persona definida ✅ Historia real ✅ Transformación cuantificable ✅ Oferta irresistible
B24: 4Ps | C24: Carruseles, posts de valor | D24: P - Promise: Promesa del resultado P - Picture: Visualización del éxito P - Proof: Evidencia/testimonio P - Push: Empuje a la acción | E24: ✅ Promesa realista ✅ Imagen mental vívida ✅ Prueba verificable ✅ Urgencia genuina
B27: 📣 BANCO DE CTAs POR OBJETIVO
B28: Objetivo | C28: CTAs para Feed/Reel | D28: CTAs para Story | E28: CTAs para Ads
B29: 💬 Comentarios | C29: "Cuéntanos en comentarios…" "¿Tú qué opinas? 👇" "Etiqueta a alguien que necesita esto" | D29: "Responde esta story 👇" "Desliza y cuéntanos" | E29: "Comenta SÍ si quieres más info"
B30: 🔗 Tráfico web | C30: "Link en bio para ver más →" "Guarda este post para cuando lo necesites" | D30: "Desliza arriba →" "Link en bio 🔗" | E30: "Haz clic para conocer más →" "Ver oferta completa"
B31: 📩 Leads / DM | C31: "Escríbenos GRATIS al DM para tu diagnóstico" "Manda un DM con la palabra [X]" | D31: "Escríbenos aquí 👆" "Responde con [palabra clave]" | E31: "Solicita tu cita gratis hoy →" "Habla con un asesor ahora"
B32: ❤️ Engagement | C32: "Guarda si te sirvió 💾" "Comparte con quien lo necesite 🔁" | D32: "Vota aquí 👆" "¿Cuál prefieres? →" | E32: "Dale me gusta si estás de acuerdo"

Sheet 🎯 Cotizador
B1: 📊 Dashboard | D1: 📅 Calendario | F1: 💰 Finanzas | H1: 🤝 CRM | J1: 🏢 Clientes | L1: 📈 Métricas | N1: ✍️ Copy & Hooks | P1: 🎯 Cotizador | R1: 📋 Reporte | T1: 💡 Ideas Hub | V1: 📖 Guía
B2: 🎯 COTIZADOR DE PROPUESTAS — PASCALL
B4: 📋 DATOS DEL CLIENTE
B5: Nombre del Cliente
B6: Industria / Giro
B7: Redes Sociales
B8: Meses de Contrato | C8: 3
B9: Inversión Publicitaria | C9: 0
B11: ⚙️ SERVICIOS A CONTRATAR
B12: Servicio | C12: Incluir? (Sí/No) | D12: Hrs/Mes | E12: Precio Base $ | F12: Precio Ajustado $ | G12: Margen %
B13: Community Management | C13: Sí | D13: 40 | E13: 8000 | F13: =IF(UPPER(C13)="SÍ",E13*(1+IF($C$8>=6,0.05,0)),0) -> 8000 | G13: =IF(UPPER(C13)="SÍ",0.6,"—") -> 0.6
B14: Creación de Contenido (básico) | C14: No | D14: 20 | E14: 5000 | F14: =IF(UPPER(C14)="SÍ",E14*(1+IF($C$8>=6,0.05,0)),0) -> 0 | G14: =IF(UPPER(C14)="SÍ",0.6,"—") -> —
B15: Creación de Contenido (premium) | C15: No | D15: 35 | E15: 12000 | F15: =IF(UPPER(C15)="SÍ",E15*(1+IF($C$8>=6,0.05,0)),0) -> 0 | G15: =IF(UPPER(C15)="SÍ",0.6,"—") -> —
B16: Gestión de Ads (Meta/TikTok) | C16: No | D16: 15 | E16: 6000 | F16: =IF(UPPER(C16)="SÍ",E16*(1+IF($C$8>=6,0.05,0)),0) -> 0 | G16: =IF(UPPER(C16)="SÍ",0.6,"—") -> —
B17: Estrategia & Consultoría | C17: No | D17: 8 | E17: 4000 | F17: =IF(UPPER(C17)="SÍ",E17*(1+IF($C$8>=6,0.05,0)),0) -> 0 | G17: =IF(UPPER(C17)="SÍ",0.6,"—") -> —
B18: Diseño Gráfico / Branding | C18: No | D18: 12 | E18: 3500 | F18: =IF(UPPER(C18)="SÍ",E18*(1+IF($C$8>=6,0.05,0)),0) -> 0 | G18: =IF(UPPER(C18)="SÍ",0.6,"—") -> —
B19: Email Marketing | C19: No | D19: 10 | E19: 3000 | F19: =IF(UPPER(C19)="SÍ",E19*(1+IF($C$8>=6,0.05,0)),0) -> 0 | G19: =IF(UPPER(C19)="SÍ",0.6,"—") -> —
B20: Reportes Mensuales | C20: No | D20: 5 | E20: 2000 | F20: =IF(UPPER(C20)="SÍ",E20*(1+IF($C$8>=6,0.05,0)),0) -> 0 | G20: =IF(UPPER(C20)="SÍ",0.6,"—") -> —
B23: 💰 RESUMEN DE PROPUESTA
B24: Servicios activos | D24: =COUNTIF(C13:C20,"Sí") -> 1
B25: Horas/mes totales | D25: =SUMIF(C13:C20,"Sí",D13:D20) -> 40
B26: Honorarios mensuales | D26: =SUM(F13:F20) -> 8000
B27: Inversión Publicitaria | D27: =C9 -> 0
B28: Total mensual cliente | D28: =SUM(F13:F20)+C9 -> 8000
B29: Total contrato completo | D29: =(SUM(F13:F20)+C9)*C8 -> 24000
B30: Tarifa por hora | D30: =IF(SUMIF(C13:C20,"Sí",D13:D20)>0,SUM(F13:F20)/SUMIF(C13:C20,"Sí",D13:D20),0) -> 200
B32: 🏆 PAQUETE RECOMENDADO
B33: =IF(SUM(F13:F20)>=20000,"🥇 PREMIUM — Propuesta de alto valor, enfócate en ROI y resultados comprobados",IF(SUM(F13:F20)>=10000,"🥈 ESTÁNDAR — Paquete sólido, destaca el valor agregado y la experiencia","🥉 STARTER — Ideal para iniciar relación, ofrece escalar en 3 meses")) -> 🥉 STARTER — Ideal para iniciar relación, ofrece escalar en 3 meses

Sheet 📋 Reporte
B1: 📊 Dashboard | D1: 📅 Calendario | F1: 💰 Finanzas | H1: 🤝 CRM | J1: 🏢 Clientes | L1: 📈 Métricas | N1: ✍️ Copy & Hooks | P1: 🎯 Cotizador | R1: 📋 Reporte | T1: 💡 Ideas Hub | V1: 📖 Guía
B2: 📋 REPORTE MENSUAL — TEMPLATE PARA CLIENTE
B4: Cliente: | C4: Clínica Derma Norte
B5: Mes / Período: | C5: Junio 2026
B7: 📊 KPIs DEL MES
B8: 👥 Seguidores Totales | C8: 0 | E8: 📣 Alcance Pagado | F8: 0
B9: 📈 Nuevos Seguidores | C9: 0 | E9: 💵 Inversión Ads | F9: 0
B10: 👁️ Alcance Orgánico | C10: 0 | E10: 💰 Retorno Generado | F10: 0
B11: 💬 Engagement Rate | C11: 0 | E11: 📊 ROAS | F11: 0
B12: 📱 Publicaciones | C12: 0 | E12: 🎯 Leads Generados | F12: 0
B13: 🔗 Clics al Perfil | C13: 0 | E13: 💲 CPL (Costo/Lead) | F13: 0
B15: 🏆 TOP CONTENIDOS DEL MES
B16: Publicación | C16: Formato | D16: Alcance | E16: Eng% | F16: Guardados | G16: Notas
B17: [Contenido #1 — llenar]
B18: [Contenido #2 — llenar]
B19: [Contenido #3 — llenar]
B21: 💡 ANÁLISIS Y RECOMENDACIONES
B22: ✅ Lo que funcionó este mes:
B23: [Escribe aquí...]
B24: ⚠️ Áreas de oportunidad:
B25: [Escribe aquí...]
B26: 🎯 Plan de acción siguiente mes:
B27: [Escribe aquí...]
B28: 📅 Próximas fechas clave:
B29: [Escribe aquí...]
B30: 🚦 SEMÁFORO DE OBJETIVOS
B31: Engagement ≥ 4% | D31: ⬜ Pendiente
B32: Crecimiento seg ≥ 2% | D32: ⬜ Pendiente
B33: ROAS ≥ 3x | D33: ⬜ Pendiente
B34: CPL ≤ $100 MXN | D34: ⬜ Pendiente

Sheet 💡 Ideas Hub
B1: 📊 Dashboard | D1: 📅 Calendario | F1: 💰 Finanzas | H1: 🤝 CRM | J1: 🏢 Clientes | L1: 📈 Métricas | N1: ✍️ Copy & Hooks | P1: 🎯 Cotizador | R1: 📋 Reporte | T1: 💡 Ideas Hub | V1: 📖 Guía
B2: 💡 IDEAS HUB — BANCO DE CONTENIDO
B3: 100+ ideas organizadas por industria, formato y objetivo. Edita y expande tu banco.
B5: Idea de Contenido | C5: Industria | D5: Formato | E5: Objetivo | F5: Hook de Apertura | G5: Prioridad
B6: Antes y después de tratamiento facial | C6: Salud/Clínica | D6: Reel | E6: Awareness | F6: ¿Cómo luce tu piel después de solo 1 sesión? 👀 | G6: 🔥 Alta
B7: 5 errores que dañan tu piel sin saberlo | C7: Salud/Clínica | D7: Carrusel | E7: Educación | F7: El error #1 que cometes cada mañana con tu piel… | G7: 🔥 Alta
B8: Rutina de skincare en 60 segundos | C8: Salud/Clínica | D8: Reel | E8: Engagement | F8: Yo en la mañana vs. yo después de este tip 😂 | G8: 🔥 Alta
B9: Mitos y verdades sobre el acné | C9: Salud/Clínica | D9: Carrusel | E9: Educación | F9: Lo que nadie te dice sobre el acné en adultos... | G9: 🟡 Media
B10: Testimonial de paciente satisfecho | C10: Salud/Clínica | D10: Video | E10: Ventas | F10: Ella no creía que funcionaría. Mira lo que pasó. | G10: 🔥 Alta
B11: Tour por las instalaciones | C11: Salud/Clínica | D11: Reel | E11: Confianza | F11: Por eso nuestros pacientes se sienten en casa 🏥 | G11: 🟡 Media
B12: Ingrediente del mes: explicación derma | C12: Salud/Clínica | D12: Carrusel | E12: Educación | F12: ¿Sabes qué le hace el retinol a tu piel realmente? | G12: 🟡 Media
B13: Checklist de cuidado solar verano | C13: Salud/Clínica | D13: Carrusel | E13: Utilidad | F13: El verano ya llegó. ¿Está tu piel lista? | G13: 🟡 Media
B14: Making of de un platillo estrella | C14: Restaurante | D14: Reel | E14: Engagement | F14: Así nace nuestro plato más pedido. 🍽️ | G14: 🔥 Alta
B15: ¿Qué pide el chef cuando nadie lo ve? | C15: Restaurante | D15: Reel | E15: Entretenimiento | F15: El chef tiene un plato favorito y no es el que crees… | G15: 🔥 Alta
B16: Receta fácil en casa (versión simplificada) | C16: Restaurante | D16: Carrusel | E16: Utilidad | F16: Aprende a hacer nuestra salsa secreta en 5 pasos | G16: 🟡 Media
... B43: Estadística sorprendente de tu industria | C43: Universal | D43: Carrusel | E43: Educación | F43: El 70% de las personas no sabe esto sobre [tu industria] | G43: 🟡 Media

Sheet 📖 Guía
B2: 📖 GUÍA DE USO — PASCALL Social Media Command Center
B7: 📊 Dashboard | C7: Vista ejecutiva. Los KPIs se actualizan automáticamente desde las otras hojas. No editar celdas azules.
B8: 📅 Calendario | C8: Agrega cada publicación: cliente, fecha, plataforma, formato y estado. Usa los filtros de columna para ver por cliente.
B9: 💰 Finanzas | C9: Ingresa ingresos y gastos en la tabla mensual (filas 19–30). El detalle por cliente actualiza el resumen automáticamente.
B10: 🤝 CRM | C10: Registra cada contacto o colaboración. Actualiza el 'Estado' conforme avanza la relación. Prioriza con Alta/Media/Baja.
B11: 🏢 Clientes | C11: Directorio central. Un registro por cliente. Los datos aquí alimentan el Dashboard.
B12: 📈 Métricas | C12: Ingresa las métricas de cada cuenta cada mes. Permite comparar rendimiento entre clientes y plataformas.
B14: ⚠️ REGLAS DE ORO
B15: 1. No borrar filas de encabezado | C15: Las fórmulas del Dashboard dependen de la estructura de cada hoja.
B16: 2. Usar los desplegables | C16: Plataforma, Estado, Prioridad tienen listas — no escribir a mano para mantener filtros consistentes.
B17: 3. Ingresos en MXN | C17: Todo el centro financiero trabaja en pesos mexicanos. Convertir antes de ingresar si es en USD.
B18: 4. Un cliente = una fila | C18: En 🏢 Clientes, cada empresa tiene una sola fila. En 📅 Calendario y 📈 Métricas puede repetirse.
B20: 🚀 Desarrollado por | C20: PASCALL Group — Monterrey, México
